Time slot   0
ld_routine
        Loaded a process at input/proc/p0s, PID: 1 PRIO: 130
Time slot   1
        CPU 0: Dispatched process  1
Time slot   2
liballoc:176
print_pgtbl:
  PDG=717a24000bb0 P4g=717a24001bc0 PUD=717a24002bd0 PMD=717a24003be0
        Loaded a process at input/proc/s3, PID: 2 PRIO: 39
Time slot   3
        CPU 3: Dispatched process  2
        CPU 0: Put process  1 to run queue
        CPU 0: Dispatched process  1
liballoc:176
print_pgtbl:
  PDG=717a24004c30 P4g=717a24005c40 PUD=717a24006c50 PMD=717a24007c60
Time slot   4
        Loaded a process at input/proc/m1s, PID: 3 PRIO: 15
        CPU 1: Dispatched process  3
liballoc:176
print_pgtbl:
  PDG=717a28000bb0 P4g=717a28001bc0 PUD=717a28002bd0 PMD=717a28003be0
Time slot   5
        CPU 0: Put process  1 to run queue
        CPU 0: Dispatched process  1
liballoc:176
print_pgtbl:
  PDG=717a28000bb0 P4g=717a28001bc0 PUD=717a28002bd0 PMD=717a28003be0
liballoc:176
print_pgtbl:
  PDG=717a28000bb0 P4g=717a28001bc0 PUD=717a28002bd0 PMD=717a28003be0
        CPU 3: Put process  2 to run queue
        CPU 3: Dispatched process  2
Time slot   6
        Loaded a process at input/proc/s2, PID: 4 PRIO: 120
libwrite:397
print_pgtbl:
  PDG=717a24008cb0 P4g=717a24009cc0 PUD=717a2400acd0 PMD=717a2400bce0
        CPU 1: Put process  3 to run queue
        CPU 1: Dispatched process  3
        CPU 3: Put process  2 to run queue
liballoc:176
Time slot   7
        CPU 2: Dispatched process  4
        CPU 3: Dispatched process  2
print_pgtbl:
  PDG=717a24008cb0 P4g=717a24009cc0 PUD=717a2400acd0 PMD=717a2400bce0
        CPU 0: Put process  1 to run queue
        CPU 0: Dispatched process  1
libread:349
print_pgtbl:
  PDG=717a24008cb0 P4g=717a24009cc0 PUD=717a2400acd0 PMD=717a2400bce0
        Loaded a process at input/proc/m0s, PID: 5 PRIO: 120
Time slot   8
libwrite:397
print_pgtbl:
        CPU 1: Put process  3 to run queue
        CPU 1: Dispatched process  3
  PDG=717a2400ccf0 P4g=717a2400dd00 PUD=717a2400ed10 PMD=717a2400fd20
        Loaded a process at input/proc/p1s, PID: 6 PRIO: 15
Time slot   9
        CPU 2: Put process  4 to run queue
        CPU 2: Dispatched process  6
        CPU 0: Put process  1 to run queue
        CPU 0: Dispatched process  5
liballoc:176
print_pgtbl:
  PDG=717a24010d70 P4g=717a24011d80 PUD=717a24012d90 PMD=717a24013da0
        CPU 3: Put process  2 to run queue
        CPU 3: Dispatched process  2
Time slot  10
liballoc:176
print_pgtbl:
  PDG=717a24010d70 P4g=717a24011d80 PUD=717a24012d90 PMD=717a24013da0
        CPU 1: Processed  3 has finished
        CPU 1: Dispatched process  4
Time slot  11
        CPU 3: Put process  2 to run queue
        CPU 2: Put process  6 to run queue
        CPU 3: Dispatched process  2
        CPU 0: Put process  5 to run queue
        CPU 0: Dispatched process  5
        CPU 2: Dispatched process  6
        Loaded a process at input/proc/s0, PID: 7 PRIO: 38
        CPU 1: Put process  4 to run queue
liballoc:176
        CPU 1: Dispatched process  7
Time slot  12
print_pgtbl:
  PDG=717a24014e30 P4g=717a24015e40 PUD=717a24016e50 PMD=717a24017e60
        CPU 3: Put process  2 to run queue
        CPU 3: Dispatched process  2
        CPU 2: Put process  6 to run queue
        CPU 2: Dispatched process  6
Time slot  13
        CPU 0: Put process  5 to run queue
        CPU 0: Dispatched process  4
        CPU 3: Processed  2 has finished
Time slot  14
        CPU 1: Put process  7 to run queue
        CPU 1: Dispatched process  7
        CPU 3: Dispatched process  5
libwrite:397
print_pgtbl:
  PDG=717a24014e30 P4g=717a24015e40 PUD=717a24016e50 PMD=717a24017e60
libwrite:397
print_pgtbl:
  PDG=717a24014e30 P4g=717a24015e40 PUD=717a24016e50 PMD=717a24017e60
Time slot  15
        CPU 0: Put process  4 to run queue
        CPU 0: Dispatched process  4
        CPU 2: Put process  6 to run queue
        CPU 2: Dispatched process  6
        CPU 3: Processed  5 has finished
Time slot  16
        Loaded a process at input/proc/s1, PID: 8 PRIO: 0
        CPU 3: Dispatched process  1
libread:349
        CPU 1: Put process  7 to run queue
        CPU 1: Dispatched process  8
print_pgtbl:
  PDG=717a1c000b70 P4g=717a1c001b80 PUD=717a1c002b90 PMD=717a1c003ba0
libwrite:397
Time slot  17
        CPU 0: Put process  4 to run queue
        CPU 0: Dispatched process  7
print_pgtbl:
  PDG=717a1c000b70 P4g=717a1c001b80 PUD=717a1c002b90 PMD=717a1c003ba0
        CPU 2: Put process  6 to run queue
        CPU 2: Dispatched process  6
        CPU 3: Put process  1 to run queue
        CPU 1: Put process  8 to run queue
        CPU 1: Dispatched process  8
        CPU 3: Dispatched process  4
Time slot  18
Time slot  19
        CPU 2: Processed  6 has finished
        CPU 2: Dispatched process  1
libread:349
print_pgtbl:
  PDG=717a1c000b70 P4g=717a1c001b80 PUD=717a1c002b90 PMD=717a1c003ba0
        CPU 0: Put process  7 to run queue
        CPU 0: Dispatched process  7
Time slot  20
        CPU 1: Put process  8 to run queue
        CPU 1: Dispatched process  8
        CPU 3: Put process  4 to run queue
        CPU 3: Dispatched process  4
        CPU 2: Put process  1 to run queue
        CPU 2: Dispatched process  1
Time slot  21
        CPU 0: Put process  7 to run queue
        CPU 0: Dispatched process  7
        CPU 3: Processed  4 has finished
        CPU 3 stopped
        CPU 1: Put process  8 to run queue
        CPU 1: Dispatched process  8
Time slot  22
        CPU 2: Processed  1 has finished
Time slot  23
        CPU 0: Put process  7 to run queue
        CPU 0: Dispatched process  7
        CPU 2 stopped
        CPU 1: Processed  8 has finished
        CPU 1 stopped
Time slot  24
Time slot  25
        CPU 0: Put process  7 to run queue
        CPU 0: Dispatched process  7
Time slot  26
Time slot  27
        CPU 0: Put process  7 to run queue
        CPU 0: Dispatched process  7
Time slot  28
        CPU 0: Processed  7 has finished
        CPU 0 stopped