Time slot   0
ld_routine
        Loaded a process at input/proc/p0s, PID: 1 PRIO: 130
Time slot   1
        CPU 3: Dispatched process  1
Time slot   2
liballoc:176
print_pgtbl:
  PDG=7aa040000bb0 P4g=7aa040001bc0 PUD=7aa040002bd0 PMD=7aa040003be0
        Loaded a process at input/proc/s3, PID: 2 PRIO: 39
        CPU 3: Put process  1 to run queue
        CPU 3: Dispatched process  2
Time slot   3
        CPU 2: Dispatched process  1
liballoc:176
print_pgtbl:
  PDG=7aa034000bb0 P4g=7aa034001bc0 PUD=7aa034002bd0 PMD=7aa034003be0
        Loaded a process at input/proc/m1s, PID: 3 PRIO: 15
Time slot   4
        CPU 0: Dispatched process  3
liballoc:176
libfree:200
print_pgtbl:
  PDG=7aa038000bb0 P4g=7aa038001bc0 PUD=7aa038002bd0 PMD=7aa038003be0
print_pgtbl:
  PDG=7aa038000bb0 P4g=7aa038001bc0 PUD=7aa038002bd0 PMD=7aa038003be0
        CPU 3: Put process  2 to run queue
liballoc:176
Time slot   5
print_pgtbl:
  PDG=7aa038000bb0 P4g=7aa038001bc0 PUD=7aa038002bd0 PMD=7aa038003be0
        CPU 3: Dispatched process  2
        CPU 2: Put process  1 to run queue
        CPU 2: Dispatched process  1
liballoc:176
print_pgtbl:
  PDG=7aa038000bb0 P4g=7aa038001bc0 PUD=7aa038002bd0 PMD=7aa038003be0
        Loaded a process at input/proc/s2, PID: 4 PRIO: 120
Time slot   6
        CPU 0: Put process  3 to run queue
        CPU 0: Dispatched process  3
libwrite:397
print_pgtbl:
  PDG=7aa034004c10 P4g=7aa034005c20 PUD=7aa034006c30 PMD=7aa034007c40
        CPU 1: Dispatched process  4
Time slot   7
        CPU 2: Put process  1 to run queue
        CPU 3: Put process  2 to run queue
        CPU 3: Dispatched process  2
liballoc:176
print_pgtbl:
  PDG=7aa034004c10 P4g=7aa034005c20 PUD=7aa034006c30 PMD=7aa034007c40
        CPU 2: Dispatched process  1
libread:349
print_pgtbl:
  PDG=7aa034004c10 P4g=7aa034005c20 PUD=7aa034006c30 PMD=7aa034007c40
        Loaded a process at input/proc/m0s, PID: 5 PRIO: 120
Time slot   8
libwrite:397
        CPU 0: Put process  3 to run queue
        CPU 0: Dispatched process  3
        CPU 1: Put process  4 to run queue
        CPU 1: Dispatched process  5
print_pgtbl:
  PDG=7aa034008c50 P4g=7aa034009c60 PUD=7aa03400ac70 PMD=7aa03400bc80
liballoc:176
print_pgtbl:
  PDG=7aa034008c50 P4g=7aa034009c60 PUD=7aa03400ac70 PMD=7aa03400bc80
        Loaded a process at input/proc/p1s, PID: 6 PRIO: 15
Time slot   9
        CPU 3: Put process  2 to run queue
        CPU 3: Dispatched process  6
        CPU 2: Put process  1 to run queue
        CPU 2: Dispatched process  2
liballoc:176
libfree:200
print_pgtbl:
  PDG=7aa02c000bf0 P4g=7aa02c001c00 PUD=7aa02c002c10 PMD=7aa02c003c20
print_pgtbl:
  PDG=7aa02c000bf0 P4g=7aa02c001c00 PUD=7aa02c002c10 PMD=7aa038004c50
Time slot  10
        CPU 1: Put process  5 to run queue
        CPU 1: Dispatched process  4
        CPU 0: Processed  3 has finished
        CPU 0: Dispatched process  5
        CPU 3: Put process  6 to run queue
        CPU 3: Dispatched process  6
        CPU 2: Put process  2 to run queue
        CPU 2: Dispatched process  2
liballoc:176
Time slot  11
        Loaded a process at input/proc/s0, PID: 7 PRIO: 38
print_pgtbl:
  PDG=7aa038005ca0 P4g=7aa038006cb0 PUD=7aa038007cc0 PMD=7aa038008cd0
Time slot  12
        CPU 1: Put process  4 to run queue
        CPU 0: Put process  5 to run queue
        CPU 0: Dispatched process  7
        CPU 1: Dispatched process  5
libwrite:397
print_pgtbl:
  PDG=7aa038005ca0 P4g=7aa038006cb0 PUD=7aa038007cc0 PMD=7aa038008cd0
        CPU 2: Put process  2 to run queue
        CPU 2: Dispatched process  2
        CPU 3: Put process  6 to run queue
        CPU 3: Dispatched process  6
libwrite:397
print_pgtbl:
  PDG=7aa038005ca0 P4g=7aa038006cb0 PUD=7aa038007cc0 PMD=7aa038008cd0
Time slot  13
        CPU 1: Processed  5 has finished
        CPU 1: Dispatched process  4
Time slot  14
        CPU 0: Put process  7 to run queue
        CPU 0: Dispatched process  7
        CPU 2: Processed  2 has finished
        CPU 2: Dispatched process  1
libread:349
print_pgtbl:
  PDG=7aa038005ca0 P4g=7aa038006cb0 PUD=7aa038007cc0 PMD=7aa038008cd0
        CPU 3: Put process  6 to run queue
        CPU 3: Dispatched process  6
libwrite:397
print_pgtbl:
  PDG=7aa038005ca0 P4g=7aa038006cb0 PUD=7aa038007cc0 PMD=7aa038008cd0
Time slot  15
        Loaded a process at input/proc/s1, PID: 8 PRIO: 0
Time slot  16
        CPU 1: Put process  4 to run queue
        CPU 1: Dispatched process  8
        CPU 2: Put process  1 to run queue
        CPU 2: Dispatched process  4
        CPU 0: Put process  7 to run queue
        CPU 0: Dispatched process  7
        CPU 3: Put process  6 to run queue
        CPU 3: Dispatched process  6
Time slot  17
Time slot  18
        CPU 1: Put process  8 to run queue
        CPU 2: Put process  4 to run queue
        CPU 2: Dispatched process  4
        CPU 1: Dispatched process  8
        CPU 0: Put process  7 to run queue
        CPU 0: Dispatched process  7
Time slot  19
        CPU 3: Processed  6 has finished
        CPU 3: Dispatched process  1
libread:349
print_pgtbl:
  PDG=7aa040004bf0 P4g=7aa040005c00 PUD=7aa040006c10 PMD=7aa040007c20
Time slot  20
        CPU 0: Put process  7 to run queue
        CPU 0: Dispatched process  7
        CPU 1: Put process  8 to run queue
        CPU 1: Dispatched process  8
        CPU 2: Put process  4 to run queue
        CPU 2: Dispatched process  4
        CPU 3: Put process  1 to run queue
        CPU 3: Dispatched process  1
Time slot  21
        CPU 1: Put process  8 to run queue
        CPU 1: Dispatched process  8
Time slot  22
        CPU 2: Processed  4 has finished
        CPU 2 stopped
        CPU 0: Put process  7 to run queue
        CPU 0: Dispatched process  7
Time slot  23
        CPU 3: Processed  1 has finished
        CPU 3 stopped
        CPU 1: Processed  8 has finished
        CPU 1 stopped
Time slot  24
        CPU 0: Put process  7 to run queue
        CPU 0: Dispatched process  7
Time slot  25
Time slot  26
        CPU 0: Put process  7 to run queue
        CPU 0: Dispatched process  7
Time slot  27
        CPU 0: Processed  7 has finished
        CPU 0 stopped