Time slot   0
ld_routine
Time slot   1
        Loaded a process at input/proc/s4, PID: 1 PRIO: 4
Time slot   2
        CPU 0: Dispatched process  1
        Loaded a process at input/proc/s3, PID: 2 PRIO: 3
Time slot   3
Time slot   4
        Loaded a process at input/proc/m1s, PID: 3 PRIO: 2
        CPU 0: Put process  1 to run queue
        CPU 0: Dispatched process  3
liballoc:176
print_pgtbl:
  PDG=76c708000bb0 P4g=76c708001bc0 PUD=76c708002bd0 PMD=76c708003be0
Time slot   5
liballoc:176
print_pgtbl:
  PDG=76c708000bb0 P4g=76c708001bc0 PUD=76c708002bd0 PMD=76c708003be0
Time slot   6
        Loaded a process at input/proc/s2, PID: 4 PRIO: 3
        CPU 0: Put process  3 to run queue
        CPU 0: Dispatched process  3
Time slot   7
liballoc:176
print_pgtbl:
  PDG=76c708004c70 P4g=76c708005c80 PUD=76c708006c90 PMD=76c708007ca0
        Loaded a process at input/proc/m0s, PID: 5 PRIO: 3
Time slot   8
        CPU 0: Put process  3 to run queue
        CPU 0: Dispatched process  3
Time slot   9
        Loaded a process at input/proc/p1s, PID: 6 PRIO: 2
Time slot  10
        CPU 0: Processed  3 has finished
        CPU 0: Dispatched process  6
Time slot  11
        Loaded a process at input/proc/s0, PID: 7 PRIO: 1
Time slot  12
        CPU 0: Put process  6 to run queue
        CPU 0: Dispatched process  7
Time slot  13
Time slot  14
        CPU 0: Put process  7 to run queue
        CPU 0: Dispatched process  7
Time slot  15
Time slot  16
        CPU 0: Put process  7 to run queue
        CPU 0: Dispatched process  7
        Loaded a process at input/proc/s1, PID: 8 PRIO: 0
Time slot  17
Time slot  18
        CPU 0: Put process  7 to run queue
        CPU 0: Dispatched process  8
Time slot  19
Time slot  20
        CPU 0: Put process  8 to run queue
        CPU 0: Dispatched process  8
Time slot  21
Time slot  22
        CPU 0: Put process  8 to run queue
        CPU 0: Dispatched process  8
Time slot  23
Time slot  24
        CPU 0: Put process  8 to run queue
        CPU 0: Dispatched process  8
Time slot  25
        CPU 0: Processed  8 has finished
        CPU 0: Dispatched process  7
Time slot  26
Time slot  27
        CPU 0: Put process  7 to run queue
        CPU 0: Dispatched process  7
Time slot  28
Time slot  29
        CPU 0: Put process  7 to run queue
        CPU 0: Dispatched process  7
Time slot  30
Time slot  31
        CPU 0: Put process  7 to run queue
        CPU 0: Dispatched process  7
Time slot  32
Time slot  33
        CPU 0: Put process  7 to run queue
        CPU 0: Dispatched process  7
Time slot  34
        CPU 0: Processed  7 has finished
        CPU 0: Dispatched process  6
Time slot  35
Time slot  36
        CPU 0: Put process  6 to run queue
        CPU 0: Dispatched process  6
Time slot  37
Time slot  38
        CPU 0: Put process  6 to run queue
        CPU 0: Dispatched process  6
Time slot  39
Time slot  40
        CPU 0: Put process  6 to run queue
        CPU 0: Dispatched process  6
Time slot  41
Time slot  42
        CPU 0: Processed  6 has finished
        CPU 0: Dispatched process  2
Time slot  43
Time slot  44
        CPU 0: Put process  2 to run queue
        CPU 0: Dispatched process  4
Time slot  45
Time slot  46
        CPU 0: Put process  4 to run queue
        CPU 0: Dispatched process  5
liballoc:176
print_pgtbl:
  PDG=76c708008cf0 P4g=76c708009d00 PUD=76c70800ad10 PMD=76c70800bd20
Time slot  47
liballoc:176
print_pgtbl:
  PDG=76c708008cf0 P4g=76c708009d00 PUD=76c70800ad10 PMD=76c70800bd20
Time slot  48
        CPU 0: Put process  5 to run queue
        CPU 0: Dispatched process  2
Time slot  49
Time slot  50
        CPU 0: Put process  2 to run queue
        CPU 0: Dispatched process  4
Time slot  51
Time slot  52
        CPU 0: Put process  4 to run queue
        CPU 0: Dispatched process  5
libfree:200
print_pgtbl:
  PDG=76c708008cf0 P4g=76c708009d00 PUD=76c70800ad10 PMD=76c70800bd20
Time slot  53
liballoc:176
print_pgtbl:
  PDG=76c708008cf0 P4g=76c708009d00 PUD=76c70800ad10 PMD=76c70800bd20
Time slot  54
        CPU 0: Put process  5 to run queue
        CPU 0: Dispatched process  2
Time slot  55
Time slot  56
        CPU 0: Put process  2 to run queue
        CPU 0: Dispatched process  4
Time slot  57
Time slot  58
        CPU 0: Put process  4 to run queue
        CPU 0: Dispatched process  5
libwrite:397
print_pgtbl:
  PDG=76c708008cf0 P4g=76c708009d00 PUD=76c70800ad10 PMD=76c70800bd20
Time slot  59
libwrite:397
print_pgtbl:
  PDG=76c708008cf0 P4g=76c708009d00 PUD=76c70800ad10 PMD=76c70800bd20
Time slot  60
        CPU 0: Processed  5 has finished
        CPU 0: Dispatched process  2
Time slot  61
Time slot  62
        CPU 0: Put process  2 to run queue
        CPU 0: Dispatched process  4
Time slot  63
Time slot  64
        CPU 0: Put process  4 to run queue
        CPU 0: Dispatched process  2
Time slot  65
Time slot  66
        CPU 0: Put process  2 to run queue
        CPU 0: Dispatched process  4
Time slot  67
Time slot  68
        CPU 0: Put process  4 to run queue
        CPU 0: Dispatched process  2
Time slot  69
        CPU 0: Processed  2 has finished
        CPU 0: Dispatched process  4
Time slot  70
Time slot  71
        CPU 0: Processed  4 has finished
        CPU 0: Dispatched process  1
Time slot  72
Time slot  73
        CPU 0: Put process  1 to run queue
        CPU 0: Dispatched process  1
Time slot  74
Time slot  75
        CPU 0: Put process  1 to run queue
        CPU 0: Dispatched process  1
Time slot  76
        CPU 0: Processed  1 has finished
        CPU 0 stopped